Workbook

Sheet tables
A1: ID | B1: ModelID | C1: Name | D1: DataCategory | E1: Description | F1: IsHidden | G1: TableStorageID | H1: ModifiedTime | I1: StructureModifiedTime | J1: SystemFlags | K1: ShowAsVariationsOnly | L1: IsPrivate | M1: DefaultDetailRowsDefinitionID | N1: AlternateSourcePrecedence | O1: RefreshPolicyID | P1: CalculationGroupID | Q1: ExcludeFromModelRefresh | R1: LineageTag | S1: SourceLineageTag | T1: SystemManaged
A2: 13 | B2: 1 | C2: ds_presupuesto_regular_dinero | F2: False | G2: 59 | H2: 45967.733 | I2: 45967.77 | J2: 0 | K2: False | L2: False | N2: 0 | Q2: False | R2: 6b3b7cce-e8ea-49fe-a148-29d6260e6bac | T2: False
A3: 16 | B3: 1 | C3: ds_presupuesto_especifico | F3: False | G3: 61 | H3: 45967.733 | I3: 45967.77 | J3: 0 | K3: False | L3: False | N3: 0 | Q3: False | R3: af76efa9-2543-4d3b-9783-31f19c5797dc | T3: False
A4: 19 | B4: 1 | C4: ds_creditos_periodo | F4: False | G4: 63 | H4: 45967.733 | I4: 45967.77 | J4: 0 | K4: False | L4: False | N4: 0 | Q4: False | R4: b1619ffd-736d-4558-bf72-1e107ce3d1fc | T4: False
A5: 388 | B5: 1 | C5: dim_deuda_nombre | F5: False | G5: 648 | H5: 45967.763 | I5: 45967.77 | J5: 0 | K5: False | L5: False | N5: 0 | Q5: False | R5: 3acc3b1f-f799-48bd-8de6-dbe8f2bb751c | T5: False
A6: 391 | B6: 1 | C6: dim_id_deuda | F6: False | G6: 650 | H6: 45967.763 | I6: 45967.77 | J6: 0 | K6: False | L6: False | N6: 0 | Q6: False | R6: fff18ebe-c929-47a0-93be-30ea15d4d0c9 | T6: False
A7: 394 | B7: 1 | C7: DateTableTemplate_717904b0-77e8-4ac0-a95d-482d70730f33 | F7: True | G7: 652 | H7: 45967.762 | I7: 45967.762 | J7: 2 | K7: False | L7: True | N7: 0 | Q7: False | R7: e9df7fca-e876-448c-a15f-11d22eb02546 | T7: False
A8: 397 | B8: 1 | C8: LocalDateTable_ef602d59-38b0-46f4-9cc4-31ba5890f364 | F8: True | G8: 654 | H8: 45967.762 | I8: 45967.762 | J8: 2 | K8: True | L8: False | N8: 0 | Q8: False | R8: 42acfb04-dd62-4a72-ba34-3d68db1596a3 | T8: False
A9: 400 | B9: 1 | C9: ds_deuda_id | F9: False | G9: 656 | H9: 45967.763 | I9: 45967.77 | J9: 0 | K9: False | L9: False | N9: 0 | Q9: False | R9: ee3a83e6-a2c6-43f1-9757-2198d8c3b128 | T9: False
A10: 403 | B10: 1 | C10: dim_tipo_credito | F10: False | G10: 658 | H10: 45967.763 | I10: 45967.77 | J10: 0 | K10: False | L10: False | N10: 0 | Q10: False | R10: adb02012-d7cb-4c98-ac3e-a742ac595e3e | T10: False
A11: 406 | B11: 1 | C11: dim_viajes_grupo | F11: False | G11: 660 | H11: 45967.763 | I11: 45967.77 | J11: 0 | K11: False | L11: False | N11: 0 | Q11: False | R11: 6c95d71e-7de4-428c-b67d-1b2f7b4d4cfa | T11: False
A12: 409 | B12: 1 | C12: LocalDateTable_7f7f7798-1c2e-4e75-a67e-974f6820ca60 | F12: True | G12: 662 | H12: 45967.762 | I12: 45967.762 | J12: 2 | K12: True | L12: False | N12: 0 | Q12: False | R12: d39fe99e-fdbe-4737-afd4-0bbe136bd10a | T12: False
A13: 412 | B13: 1 | C13: LocalDateTable_7bedd17d-64fe-4231-9ee4-b6a2cba9c4fe | F13: True | G13: 664 | H13: 45967.762 | I13: 45967.762 | J13: 2 | K13: True | L13: False | N13: 0 | Q13: False | R13: 26a2a276-2681-4379-ac03-d4e950a12e29 | T13: False
... A41: 11641 | B41: 1 | C41: ds_presupuesto_mensual_regular_dinero | F41: False | G41: 11765 | H41: 45967.87 | I41: 45967.87 | J41: 0 | K41: False | L41: False | N41: 0 | Q41: False | R41: f90d0845-6ea0-412d-ba8d-b108ad2ab2d3 | T41: False

Sheet columns
A1: ID | B1: TableID | C1: ExplicitName | D1: InferredName | E1: ExplicitDataType | F1: InferredDataType | G1: DataCategory | H1: Description | I1: IsHidden | J1: State | K1: IsUnique | L1: IsKey | M1: IsNullable | N1: Alignment | O1: TableDetailPosition | P1: IsDefaultLabel | Q1: IsDefaultImage | R1: SummarizeBy | S1: ColumnStorageID | T1: Type | U1: SourceColumn | V1: ColumnOriginID | W1: Expression | X1: FormatString | Y1: IsAvailableInMDX | Z1: SortByColumnID | AA1: AttributeHierarchyID | AB1: ModifiedTime | AC1: StructureModifiedTime | AD1: RefreshedTime | AE1: SystemFlags | AF1: KeepUniqueRows | AG1: DisplayOrdinal | AH1: ErrorMessage | AI1: SourceProviderType | AJ1: DisplayFolder | AK1: EncodingHint | AL1: RelatedColumnDetailsID | AM1: AlternateOfID | AN1: LineageTag | AO1: SourceLineageTag
A2: 14 | B2: 13 | C2: RowNumber-2662979B-1795-4F74-8F37-6A1BA8059B61 | E2: 6 | F2: 19 | I2: True | J2: 1 | K2: True | L2: True | M2: False | N2: 1 | O2: -1 | P2: False | Q2: False | R2: 1 | S2: 74 | T2: 3 | Y2: True | AA2: 15 | AB2: 45967.73 | AC2: 45967.73 | AD2: 31/12/1699 12:00:00 a. m. | AE2: 0 | AF2: False | AG2: 0 | AK2: 0
A3: 22 | B3: 13 | C3: id | E3: 2 | F3: 19 | I3: False | J3: 1 | K3: False | L3: False | M3: True | N3: 1 | O3: -1 | P3: False | Q3: False | R3: 2 | S3: 86 | T3: 1 | U3: id | Y3: True | AA3: 49 | AB3: 45967.73 | AC3: 45967.73 | AD3: 31/12/1699 12:00:00 a. m. | AE3: 0 | AF3: False | AG3: 0 | AK3: 0 | AN3: c0382ce4-8a8a-4d6e-ba88-7b64b6684096
A4: 23 | B4: 13 | C4: tipo_razon_uso | E4: 2 | F4: 19 | I4: True | J4: 1 | K4: False | L4: False | M4: True | N4: 1 | O4: -1 | P4: False | Q4: False | R4: 2 | S4: 90 | T4: 1 | U4: tipo_razon_uso | Y4: True | AA4: 50 | AB4: 45968.728 | AC4: 45968.728 | AD4: 31/12/1699 12:00:00 a. m. | AE4: 0 | AF4: False | AG4: 0 | AK4: 0 | AN4: ef4471b2-e482-4ed8-822c-bb38a599f4c7
A5: 24 | B5: 13 | C5: grupo_viaje | E5: 2 | F5: 19 | I5: False | J5: 1 | K5: False | L5: False | M5: True | N5: 1 | O5: -1 | P5: False | Q5: False | R5: 2 | S5: 94 | T5: 1 | U5: grupo_viaje | Y5: True | AA5: 51 | AB5: 45967.73 | AC5: 45967.73 | AD5: 31/12/1699 12:00:00 a. m. | AE5: 0 | AF5: False | AG5: 0 | AK5: 0 | AN5: 7953a221-4b9b-44b1-b110-63253553b3af
A6: 17 | B6: 16 | C6: RowNumber-2662979B-1795-4F74-8F37-6A1BA8059B61 | E6: 6 | F6: 19 | I6: True | J6: 1 | K6: True | L6: True | M6: False | N6: 1 | O6: -1 | P6: False | Q6: False | R6: 1 | S6: 78 | T6: 3 | Y6: True | AA6: 18 | AB6: 45967.73 | AC6: 45967.73 | AD6: 31/12/1699 12:00:00 a. m. | AE6: 0 | AF6: False | AG6: 0 | AK6: 0
A7: 25 | B7: 16 | C7: id | E7: 2 | F7: 19 | I7: False | J7: 1 | K7: False | L7: False | M7: True | N7: 1 | O7: -1 | P7: False | Q7: False | R7: 2 | S7: 98 | T7: 1 | U7: id | Y7: True | AA7: 52 | AB7: 45967.73 | AC7: 45967.73 | AD7: 31/12/1699 12:00:00 a. m. | AE7: 0 | AF7: False | AG7: 0 | AK7: 0 | AN7: 7398c289-6ac7-4d7b-8957-265ec491ee05
A8: 26 | B8: 16 | C8: id_presupuesto | E8: 2 | F8: 19 | I8: False | J8: 1 | K8: False | L8: False | M8: True | N8: 1 | O8: -1 | P8: False | Q8: False | R8: 2 | S8: 102 | T8: 1 | U8: id_presupuesto | Y8: True | AA8: 53 | AB8: 45967.73 | AC8: 45967.73 | AD8: 31/12/1699 12:00:00 a. m. | AE8: 0 | AF8: False | AG8: 0 | AK8: 0 | AN8: 8dc70881-33a7-48f4-bfa4-9aebda7b560f
A9: 27 | B9: 16 | C9: grupo_viaje | E9: 2 | F9: 19 | I9: False | J9: 1 | K9: False | L9: False | M9: True | N9: 1 | O9: -1 | P9: False | Q9: False | R9: 2 | S9: 106 | T9: 1 | U9: grupo_viaje | Y9: True | AA9: 54 | AB9: 45967.73 | AC9: 45967.73 | AD9: 31/12/1699 12:00:00 a. m. | AE9: 0 | AF9: False | AG9: 0 | AK9: 0 | AN9: d91e7d47-a98e-4463-b05d-a6c207e67ced
A10: 20 | B10: 19 | C10: RowNumber-2662979B-1795-4F74-8F37-6A1BA8059B61 | E10: 6 | F10: 19 | I10: True | J10: 1 | K10: True | L10: True | M10: False | N10: 1 | O10: -1 | P10: False | Q10: False | R10: 1 | S10: 82 | T10: 3 | Y10: True | AA10: 21 | AB10: 45967.73 | AC10: 45967.73 | AD10: 31/12/1699 12:00:00 a. m. | AE10: 0 | AF10: False | AG10: 0 | AK10: 0
A11: 28 | B11: 19 | C11: id | E11: 2 | F11: 19 | I11: False | J11: 1 | K11: False | L11: False | M11: True | N11: 1 | O11: -1 | P11: False | Q11: False | R11: 2 | S11: 110 | T11: 1 | U11: id | Y11: True | AA11: 55 | AB11: 45967.73 | AC11: 45967.73 | AD11: 31/12/1699 12:00:00 a. m. | AE11: 0 | AF11: False | AG11: 0 | AK11: 0 | AN11: 7f03275a-dd0f-47f9-86db-723db5e43487
A12: 29 | B12: 19 | C12: periodo_inicio | E12: 6 | F12: 19 | I12: False | J12: 1 | K12: False | L12: False | M12: True | N12: 1 | O12: -1 | P12: False | Q12: False | R12: 3 | S12: 114 | T12: 1 | U12: periodo_inicio | X12: 0 | Y12: True | AA12: 56 | AB12: 45967.73 | AC12: 45967.73 | AD12: 31/12/1699 12:00:00 a. m. | AE12: 0 | AF12: False | AG12: 0 | AK12: 0 | AN12: b84cd9e2-6840-47dd-8ac2-0bc895abc2ba
A13: 30 | B13: 19 | C13: periodo_corte | E13: 6 | F13: 19 | I13: False | J13: 1 | K13: False | L13: False | M13: True | N13: 1 | O13: -1 | P13: False | Q13: False | R13: 3 | S13: 118 | T13: 1 | U13: periodo_corte | X13: 0 | Y13: True | AA13: 57 | AB13: 45967.73 | AC13: 45967.73 | AD13: 31/12/1699 12:00:00 a. m. | AE13: 0 | AF13: False | AG13: 0 | AK13: 0 | AN13: f4e9a711-2883-4216-affc-7a20715183f5
A14: 31 | B14: 19 | C14: tipo_credito | E14: 2 | F14: 19 | I14: False | J14: 1 | K14: False | L14: False | M14: True | N14: 1 | O14: -1 | P14: False | Q14: False | R14: 2 | S14: 122 | T14: 1 | U14: tipo_credito | Y14: True | AA14: 58 | AB14: 45967.73 | AC14: 45967.73 | AD14: 31/12/1699 12:00:00 a. m. | AE14: 0 | AF14: False | AG14: 0 | AK14: 0 | AN14: 8c6e41b7-b2ef-4e84-bb3b-d2911480dc7c
A15: 389 | B15: 388 | C15: RowNumber-2662979B-1795-4F74-8F37-6A1BA8059B61 | E15: 6 | F15: 19 | I15: True | J15: 1 | K15: True | L15: True | M15: False | N15: 1 | O15: -1 | P15: False | Q15: False | R15: 1 | S15: 703 | T15: 3 | Y15: True | AA15: 390 | AB15: 45967.762 | AC15: 45967.762 | AD15: 31/12/1699 12:00:00 a. m. | AE15: 0 | AF15: False | AG15: 0 | AK15: 0
A16: 424 | B16: 388 | C16: nombre_deudor | E16: 2 | F16: 19 | I16: False | J16: 1 | K16: False | L16: False | M16: True | N16: 1 | O16: -1 | P16: False | Q16: False | R16: 2 | S16: 747 | T16: 1 | U16: nombre_deudor | Y16: True | AA16: 599 | AB16: 45967.762 | AC16: 45967.762 | AD16: 31/12/1699 12:00:00 a. m. | AE16: 0 | AF16: False | AG16: 0 | AK16: 0 | AN16: 4d60cf25-7a9b-4423-9dfb-910dba26d35d
A17: 392 | B17: 391 | C17: RowNumber-2662979B-1795-4F74-8F37-6A1BA8059B61 | E17: 6 | F17: 19 | I17: True | J17: 1 | K17: True | L17: True | M17: False | N17: 1 | O17: -1 | P17: False | Q17: False | R17: 1 | S17: 707 | T17: 3 | Y17: True | AA17: 393 | AB17: 45967.762 | AC17: 45967.762 | AD17: 31/12/1699 12:00:00 a. m. | AE17: 0 | AF17: False | AG17: 0 | AK17: 0
A18: 425 | B18: 391 | C18: id_deuda | E18: 2 | F18: 19 | I18: False | J18: 1 | K18: False | L18: False | M18: True | N18: 1 | O18: -1 | P18: False | Q18: False | R18: 2 | S18: 751 | T18: 1 | U18: id_deuda | Y18: True | AA18: 600 | AB18: 45967.762 | AC18: 45967.762 | AD18: 31/12/1699 12:00:00 a. m. | AE18: 0 | AF18: False | AG18: 0 | AK18: 0 | AN18: e79a1113-3ddd-4df8-81c1-5d41f64470b5
A19: 426 | B19: 391 | C19: descripcion | E19: 2 | F19: 19 | I19: False | J19: 1 | K19: False | L19: False | M19: True | N19: 1 | O19: -1 | P19: False | Q19: False | R19: 2 | S19: 755 | T19: 1 | U19: descripcion | Y19: True | AA19: 601 | AB19: 45967.762 | AC19: 45967.762 | AD19: 31/12/1699 12:00:00 a. m. | AE19: 0 | AF19: False | AG19: 0 | AK19: 0 | AN19: b04a28b1-33e6-4692-ac08-a043315b773d
A20: 427 | B20: 391 | C20: fecha_inicio | E20: 9 | F20: 19 | I20: False | J20: 1 | K20: False | L20: False | M20: True | N20: 1 | O20: -1 | P20: False | Q20: False | R20: 2 | S20: 759 | T20: 1 | U20: fecha_inicio | X20: Long Date | Y20: True | AA20: 602 | AB20: 45967.762 | AC20: 45967.762 | AD20: 31/12/1699 12:00:00 a. m. | AE20: 0 | AF20: False | AG20: 0 | AK20: 0 | AN20: d80ebcd7-8c3f-4da3-aac5-e1080fc9de80
A21: 442 | B21: 391 | C21: finalizado | E21: 2 | F21: 19 | I21: False | J21: 1 | K21: False | L21: False | M21: True | N21: 1 | O21: -1 | P21: False | Q21: False | R21: 2 | S21: 819 | T21: 1 | U21: finalizado | Y21: True | AA21: 617 | AB21: 45967.762 | AC21: 45967.762 | AD21: 31/12/1699 12:00:00 a. m. | AE21: 0 | AF21: False | AG21: 0 | AK21: 0 | AN21: 099006ba-7c69-4c8d-8859-fcbef4aea915
A22: 443 | B22: 391 | C22: periodo_id_deuda | E22: 6 | F22: 19 | I22: False | J22: 1 | K22: False | L22: False | M22: True | N22: 1 | O22: -1 | P22: False | Q22: False | R22: 3 | S22: 823 | T22: 1 | U22: periodo_id_deuda | X22: 0 | Y22: True | AA22: 618 | AB22: 45967.762 | AC22: 45967.762 | AD22: 31/12/1699 12:00:00 a. m. | AE22: 0 | AF22: False | AG22: 0 | AK22: 0 | AN22: 9934b27d-e16b-49d4-b7c4-713b18e8ab9f
A23: 395 | B23: 394 | C23: RowNumber-2662979B-1795-4F74-8F37-6A1BA8059B61 | E23: 6 | F23: 19 | I23: True | J23: 1 | K23: True | L23: True | M23: False | N23: 1 | O23: -1 | P23: False | Q23: False | R23: 1 | S23: 711 | T23: 3 | Y23: True | AA23: 396 | AB23: 45967.762 | AC23: 45967.762 | AD23: 31/12/1699 12:00:00 a. m. | AE23: 2 | AF23: False | AG23: 0 | AK23: 0
A24: 428 | B24: 394 | D24: Date | E24: 9 | F24: 9 | G24: PaddedDateTableDates | I24: True | J24: 1 | K24: False | L24: False | M24: True | N24: 1 | O24: -1 | P24: False | Q24: False | R24: 2 | S24: 763 | T24: 4 | U24: [Date] | X24: General Date | Y24: True | AA24: 603 | AB24: 45967.762 | AC24: 45967.762 | AD24: 31/12/1699 12:00:00 a. m. | AE24: 2 | AF24: False | AG24: 0 | AK24: 0 | AN24: 36213d03-c5d0-4efe-b4f5-a79673bd48c0
A25: 429 | B25: 394 | C25: Year | E25: 6 | F25: 6 | G25: Years | I25: True | J25: 1 | K25: False | L25: False | M25: True | N25: 1 | O25: -1 | P25: False | Q25: False | R25: 2 | S25: 767 | T25: 2 | W25: YEAR([Date]) | X25: 0 | Y25: True | AA25: 604 | AB25: 45967.762 | AC25: 45967.762 | AD25: 45967.762 | AE25: 2 | AF25: False | AG25: 0 | AK25: 0 | AN25: 8098c5dd-3523-4ff9-8cd1-1d96915c643e
A26: 430 | B26: 394 | C26: MonthNo | E26: 6 | F26: 6 | G26: MonthOfYear | I26: True | J26: 1 | K26: False | L26: False | M26: True | N26: 1 | O26: -1 | P26: False | Q26: False | R26: 2 | S26: 771 | T26: 2 | W26: MONTH([Date]) | X26: 0 | Y26: True | AA26: 605 | AB26: 45967.762 | AC26: 45967.762 | AD26: 45967.762 | AE26: 2 | AF26: False | AG26: 0 | AK26: 0 | AN26: 745b4f4f-f7c5-4da7-a386-684e69dedb91
A27: 431 | B27: 394 | C27: Month | E27: 2 | F27: 2 | G27: Months | I27: True | J27: 1 | K27: False | L27: False | M27: True | N27: 1 | O27: -1 | P27: False | Q27: False | R27: 2 | S27: 775 | T27: 2 | W27: FORMAT([Date], "MMMM") | Y27: True | Z27: 430 | AA27: 606 | AB27: 45967.762 | AC27: 45967.762 | AD27: 45967.762 | AE27: 2 | AF27: False | AG27: 0 | AK27: 0 | AN27: 451cec7f-3087-4086-b538-22b36349e6f4
A28: 432 | B28: 394 | C28: QuarterNo | E28: 6 | F28: 6 | G28: QuarterOfYear | I28: True | J28: 1 | K28: False | L28: False | M28: True | N28: 1 | O28: -1 | P28: False | Q28: False | R28: 2 | S28: 779 | T28: 2 | W28: INT(([MonthNo] + 2) / 3) | X28: 0 | Y28: True | AA28: 607 | AB28: 45967.762 | AC28: 45967.762 | AD28: 45967.762 | AE28: 2 | AF28: False | AG28: 0 | AK28: 0 | AN28: 74e1fbc8-354e-40a5-8f72-b0139ea8227b
A29: 433 | B29: 394 | C29: Quarter | E29: 2 | F29: 2 | G29: Quarters | I29: True | J29: 1 | K29: False | L29: False | M29: True | N29: 1 | O29: -1 | P29: False | Q29: False | R29: 2 | S29: 783 | T29: 2 | W29: Qtr & [QuarterNo] | Y29: True | Z29: 432 | AA29: 608 | AB29: 45967.762 | AC29: 45967.762 | AD29: 45967.762 | AE29: 2 | AF29: False | AG29: 0 | AK29: 0 | AN29: 287f395d-c2a4-405c-92a6-6b9bdb64f0f8
A30: 434 | B30: 394 | C30: Day | E30: 6 | F30: 6 | G30: DayOfMonth | I30: True | J30: 1 | K30: False | L30: False | M30: True | N30: 1 | O30: -1 | P30: False | Q30: False | R30: 2 | S30: 787 | T30: 2 | W30: DAY([Date]) | X30: 0 | Y30: True | AA30: 609 | AB30: 45967.762 | AC30: 45967.762 | AD30: 45967.762 | AE30: 2 | AF30: False | AG30: 0 | AK30: 0 | AN30: cf8e9113-e06c-409d-a9ff-62a3d90560af
A31: 398 | B31: 397 | C31: RowNumber-2662979B-1795-4F74-8F37-6A1BA8059B61 | E31: 6 | F31: 19 | I31: True | J31: 1 | K31: True | L31: True | M31: False | N31: 1 | O31: -1 | P31: False | Q31: False | R31: 1 | S31: 715 | T31: 3 | Y31: True | AA31: 399 | AB31: 45967.77 | AC31: 45967.762 | AD31: 31/12/1699 12:00:00 a. m. | AE31: 2 | AF31: False | AG31: 0 | AK31: 0
A32: 435 | B32: 397 | D32: Date | E32: 9 | F32: 9 | G32: PaddedDateTableDates | I32: True | J32: 1 | K32: False | L32: False | M32: True | N32: 1 | O32: -1 | P32: False | Q32: False | R32: 2 | S32: 791 | T32: 4 | U32: [Date] | X32: General Date | Y32: True | AA32: 610 | AB32: 45967.77 | AC32: 45967.762 | AD32: 31/12/1699 12:00:00 a. m. | AE32: 2 | AF32: False | AG32: 0 | AK32: 0 | AN32: 5f6f1a5e-497e-4fde-968c-7fd88835e88e
A33: 436 | B33: 397 | C33: Year | E33: 6 | F33: 6 | G33: Years | I33: True | J33: 1 | K33: False | L33: False | M33: True | N33: 1 | O33: -1 | P33: False | Q33: False | R33: 2 | S33: 795 | T33: 2 | W33: YEAR([Date]) | X33: 0 | Y33: True | AA33: 611 | AB33: 45967.77 | AC33: 45967.762 | AD33: 45967.77 | AE33: 2 | AF33: False | AG33: 0 | AK33: 0 | AN33: 041eae69-bd59-4d96-9956-95074f60e55c
A34: 437 | B34: 397 | C34: MonthNo | E34: 6 | F34: 6 | G34: MonthOfYear | I34: True | J34: 1 | K34: False | L34: False | M34: True | N34: 1 | O34: -1 | P34: False | Q34: False | R34: 2 | S34: 799 | T34: 2 | W34: MONTH([Date]) | X34: 0 | Y34: True | AA34: 612 | AB34: 45967.77 | AC34: 45967.762 | AD34: 45967.77 | AE34: 2 | AF34: False | AG34: 0 | AK34: 0 | AN34: d0fdeabc-2f62-496a-9bb3-8e666e85b448
A35: 438 | B35: 397 | C35: Month | E35: 2 | F35: 2 | G35: Months | I35: True | J35: 1 | K35: False | L35: False | M35: True | N35: 1 | O35: -1 | P35: False | Q35: False | R35: 2 | S35: 803 | T35: 2 | W35: FORMAT([Date], "MMMM") | Y35: True | Z35: 437 | AA35: 613 | AB35: 45967.77 | AC35: 45967.762 | AD35: 45967.77 | AE35: 2 | AF35: False | AG35: 0 | AK35: 0 | AN35: ab6822b6-0e3f-4a32-aa55-e8a92675da41
A36: 439 | B36: 397 | C36: QuarterNo | E36: 6 | F36: 6 | G36: QuarterOfYear | I36: True | J36: 1 | K36: False | L36: False | M36: True | N36: 1 | O36: -1 | P36: False | Q36: False | R36: 2 | S36: 807 | T36: 2 | W36: INT(([MonthNo] + 2) / 3) | X36: 0 | Y36: True | AA36: 614 | AB36: 45967.77 | AC36: 45967.762 | AD36: 45967.77 | AE36: 2 | AF36: False | AG36: 0 | AK36: 0 | AN36: ea61bc36-49a9-4537-864c-fd3a3a958634
A37: 440 | B37: 397 | C37: Quarter | E37: 2 | F37: 2 | G37: Quarters | I37: True | J37: 1 | K37: False | L37: False | M37: True | N37: 1 | O37: -1 | P37: False | Q37: False | R37: 2 | S37: 811 | T37: 2 | W37: Qtr & [QuarterNo] | Y37: True | Z37: 439 | AA37: 615 | AB37: 45967.77 | AC37: 45967.762 | AD37: 45967.77 | AE37: 2 | AF37: False | AG37: 0 | AK37: 0 | AN37: 9de611e8-cdcb-4fcb-b55b-738eda50fa48
A38: 441 | B38: 397 | C38: Day | E38: 6 | F38: 6 | G38: DayOfMonth | I38: True | J38: 1 | K38: False | L38: False | M38: True | N38: 1 | O38: -1 | P38: False | Q38: False | R38: 2 | S38: 815 | T38: 2 | W38: DAY([Date]) | X38: 0 | Y38: True | AA38: 616 | AB38: 45967.77 | AC38: 45967.762 | AD38: 45967.77 | AE38: 2 | AF38: False | AG38: 0 | AK38: 0 | AN38: ba9aea16-93ef-4b04-b4e7-f3fe7dcefdda
A39: 401 | B39: 400 | C39: RowNumber-2662979B-1795-4F74-8F37-6A1BA8059B61 | E39: 6 | F39: 19 | I39: True | J39: 1 | K39: True | L39: True | M39: False | N39: 1 | O39: -1 | P39: False | Q39: False | R39: 1 | S39: 719 | T39: 3 | Y39: True | AA39: 402 | AB39: 45967.762 | AC39: 45967.762 | AD39: 31/12/1699 12:00:00 a. m. | AE39: 0 | AF39: False | AG39: 0 | AK39: 0
A40: 444 | B40: 400 | C40: id | E40: 2 | F40: 19 | I40: False | J40: 1 | K40: False | L40: False | M40: True | N40: 1 | O40: -1 | P40: False | Q40: False | R40: 2 | S40: 827 | T40: 1 | U40: id | Y40: True | AA40: 619 | AB40: 45967.762 | AC40: 45967.762 | AD40: 31/12/1699 12:00:00 a. m. | AE40: 0 | AF40: False | AG40: 0 | AK40: 0 | AN40: 3eabf073-b08a-4143-8d39-9cfa57eb7f1e
...

Sheet relationships
A1: ID | B1: ModelID | C1: Name | D1: IsActive | E1: Type | F1: CrossFilteringBehavior | H1: JoinOnDateBehavior | I1: RelyOnReferentialIntegrity | J1: FromTableID | L1: FromColumnID | N1: FromCardinality | P1: ToTableID | R1: ToColumnID | T1: ToCardinality | V1: Cardinality | W1: State | X1: RelationshipStorageID | Y1: RelationshipStorage2ID | Z1: ModifiedTime | AA1: RefreshedTime | AB1: SecurityFilteringBehavior
A2: 421 | B2: 1 | C2: 066af2fb-868e-499c-b340-db9a8f0020cf | D2: True | E2: 1 | F2: 1 | G2: =IF(F2=1,"Single", "Both") -> Single | H2: 2 | I2: False | J2: 391 | K2: =_xlfn.XLOOKUP(J2,tables!A:A,tables!C:C) -> dim_id_deuda | L2: 427 | M2: =_xlfn.XLOOKUP(L2,columns!A:A,columns!C:C) -> fecha_inicio | N2: 2 | O2: =IF(N2=2,"Many","One") -> Many | P2: 397 | Q2: =_xlfn.XLOOKUP(P2,tables!A:A,tables!C:C) -> LocalDateTable_ef602d59-38b0-46f4-9cc4-31ba5890f364 | R2: 435 | S2: =_xlfn.XLOOKUP(R2,columns!A:A,columns!C:C) -> 0 | T2: 1 | U2: =IF(T2=2,"Many","One") -> One | V2: =O2 &"-to-"&U2 -> Many-to-One | W2: 1 | X2: 943 | Z2: 45967.77 | AA2: 45967.77 | AB2: 1
A3: 422 | B3: 1 | C3: c1785360-d268-4722-b542-d36b919265e4 | D3: True | E3: 1 | F3: 1 | G3: =IF(F3=1,"Single", "Both") -> Single | H3: 2 | I3: False | J3: 406 | K3: =_xlfn.XLOOKUP(J3,tables!A:A,tables!C:C) -> dim_viajes_grupo | L3: 452 | M3: =_xlfn.XLOOKUP(L3,columns!A:A,columns!C:C) -> primera_fecha | N3: 2 | O3: =IF(N3=2,"Many","One") -> Many | P3: 409 | Q3: =_xlfn.XLOOKUP(P3,tables!A:A,tables!C:C) -> LocalDateTable_7f7f7798-1c2e-4e75-a67e-974f6820ca60 | R3: 453 | S3: =_xlfn.XLOOKUP(R3,columns!A:A,columns!C:C) -> 0 | T3: 1 | U3: =IF(T3=2,"Many","One") -> One | V3: =O3 &"-to-"&U3 -> Many-to-One | W3: 1 | X3: 945 | Z3: 45967.77 | AA3: 45967.77 | AB3: 1
A4: 423 | B4: 1 | C4: 322cad84-14ba-4b4c-bf2f-2b1c67977a1a | D4: True | E4: 1 | F4: 1 | G4: =IF(F4=1,"Single", "Both") -> Single | H4: 2 | I4: False | J4: 406 | K4: =_xlfn.XLOOKUP(J4,tables!A:A,tables!C:C) -> dim_viajes_grupo | L4: 460 | M4: =_xlfn.XLOOKUP(L4,columns!A:A,columns!C:C) -> ultima_fecha | N4: 2 | O4: =IF(N4=2,"Many","One") -> Many | P4: 412 | Q4: =_xlfn.XLOOKUP(P4,tables!A:A,tables!C:C) -> LocalDateTable_7bedd17d-64fe-4231-9ee4-b6a2cba9c4fe | R4: 461 | S4: =_xlfn.XLOOKUP(R4,columns!A:A,columns!C:C) -> 0 | T4: 1 | U4: =IF(T4=2,"Many","One") -> One | V4: =O4 &"-to-"&U4 -> Many-to-One | W4: 1 | X4: 947 | Z4: 45967.77 | AA4: 45967.77 | AB4: 1
A5: 3819 | B5: 1 | C5: 2a1d75c3-176d-417e-9418-8db6ee3202d8 | D5: True | E5: 1 | F5: 1 | G5: =IF(F5=1,"Single", "Both") -> Single | H5: 2 | I5: False | J5: 3740 | K5: =_xlfn.XLOOKUP(J5,tables!A:A,tables!C:C) -> fact_creditos | L5: 3849 | M5: =_xlfn.XLOOKUP(L5,columns!A:A,columns!C:C) -> fecha_inicio | N5: 2 | O5: =IF(N5=2,"Many","One") -> Many | P5: 3743 | Q5: =_xlfn.XLOOKUP(P5,tables!A:A,tables!C:C) -> LocalDateTable_8bfe11d8-9d64-432e-95fa-9e38282ea2b3 | R5: 3850 | S5: =_xlfn.XLOOKUP(R5,columns!A:A,columns!C:C) -> 0 | T5: 1 | U5: =IF(T5=2,"Many","One") -> One | V5: =O5 &"-to-"&U5 -> Many-to-One | W5: 1 | X5: 5466 | Z5: 45967.778 | AA5: 45967.778 | AB5: 1
A6: 3821 | B6: 1 | C6: befa0443-0736-4b65-b65a-cb08dda86309 | D6: True | E6: 1 | F6: 1 | G6: =IF(F6=1,"Single", "Both") -> Single | H6: 2 | I6: False | J6: 3740 | K6: =_xlfn.XLOOKUP(J6,tables!A:A,tables!C:C) -> fact_creditos | L6: 3865 | M6: =_xlfn.XLOOKUP(L6,columns!A:A,columns!C:C) -> fecha_limite_pago | N6: 2 | O6: =IF(N6=2,"Many","One") -> Many | P6: 3749 | Q6: =_xlfn.XLOOKUP(P6,tables!A:A,tables!C:C) -> LocalDateTable_3681210b-a335-4c77-ac03-01e6f68ab879 | R6: 3866 | S6: =_xlfn.XLOOKUP(R6,columns!A:A,columns!C:C) -> 0 | T6: 1 | U6: =IF(T6=2,"Many","One") -> One | V6: =O6 &"-to-"&U6 -> Many-to-One | W6: 1 | X6: 5470 | Z6: 45967.778 | AA6: 45967.778 | AB6: 1
A7: 3824 | B7: 1 | C7: ac75c67e-c0c2-4429-b0bc-2bc140c566a9 | D7: True | E7: 1 | F7: 1 | G7: =IF(F7=1,"Single", "Both") -> Single | H7: 2 | I7: False | J7: 3764 | K7: =_xlfn.XLOOKUP(J7,tables!A:A,tables!C:C) -> fact_presupuesto | L7: 3906 | M7: =_xlfn.XLOOKUP(L7,columns!A:A,columns!C:C) -> inicio_mes | N7: 2 | O7: =IF(N7=2,"Many","One") -> Many | P7: 3767 | Q7: =_xlfn.XLOOKUP(P7,tables!A:A,tables!C:C) -> LocalDateTable_b6fb53e3-b7ba-4c74-884e-ccca74952e66 | R7: 3907 | S7: =_xlfn.XLOOKUP(R7,columns!A:A,columns!C:C) -> 0 | T7: 1 | U7: =IF(T7=2,"Many","One") -> One | V7: =O7 &"-to-"&U7 -> Many-to-One | W7: 1 | X7: 5476 | Z7: 45967.778 | AA7: 45967.778 | AB7: 1
A8: 3825 | B8: 1 | C8: c548da7b-2daf-4acc-8556-a319af7576b6 | D8: True | E8: 1 | F8: 1 | G8: =IF(F8=1,"Single", "Both") -> Single | H8: 2 | I8: False | J8: 3764 | K8: =_xlfn.XLOOKUP(J8,tables!A:A,tables!C:C) -> fact_presupuesto | L8: 3914 | M8: =_xlfn.XLOOKUP(L8,columns!A:A,columns!C:C) -> final_mes | N8: 2 | O8: =IF(N8=2,"Many","One") -> Many | P8: 3770 | Q8: =_xlfn.XLOOKUP(P8,tables!A:A,tables!C:C) -> LocalDateTable_e91d21ee-56d7-4dd0-96ca-26396628605f | R8: 3915 | S8: =_xlfn.XLOOKUP(R8,columns!A:A,columns!C:C) -> 0 | T8: 1 | U8: =IF(T8=2,"Many","One") -> One | V8: =O8 &"-to-"&U8 -> Many-to-One | W8: 1 | X8: 5478 | Z8: 45967.778 | AA8: 45967.778 | AB8: 1
A9: 3826 | B9: 1 | C9: 480d6912-0461-49d0-a7cc-9f2b44a025ac | D9: True | E9: 1 | F9: 1 | G9: =IF(F9=1,"Single", "Both") -> Single | H9: 2 | I9: False | J9: 3785 | K9: =_xlfn.XLOOKUP(J9,tables!A:A,tables!C:C) -> dim_id_viajes | L9: 3952 | M9: =_xlfn.XLOOKUP(L9,columns!A:A,columns!C:C) -> desde | N9: 2 | O9: =IF(N9=2,"Many","One") -> Many | P9: 3788 | Q9: =_xlfn.XLOOKUP(P9,tables!A:A,tables!C:C) -> LocalDateTable_59fd308b-cf98-4ef8-ae5b-199f77810806 | R9: 3953 | S9: =_xlfn.XLOOKUP(R9,columns!A:A,columns!C:C) -> 0 | T9: 1 | U9: =IF(T9=2,"Many","One") -> One | V9: =O9 &"-to-"&U9 -> Many-to-One | W9: 1 | X9: 5480 | Z9: 45967.778 | AA9: 45967.778 | AB9: 1
A10: 3827 | B10: 1 | C10: 98028ae4-8b2a-44ca-9d4c-2936ff8b962b | D10: True | E10: 1 | F10: 1 | G10: =IF(F10=1,"Single", "Both") -> Single | H10: 2 | I10: False | J10: 3785 | K10: =_xlfn.XLOOKUP(J10,tables!A:A,tables!C:C) -> dim_id_viajes | L10: 3960 | M10: =_xlfn.XLOOKUP(L10,columns!A:A,columns!C:C) -> hasta | N10: 2 | O10: =IF(N10=2,"Many","One") -> Many | P10: 3791 | Q10: =_xlfn.XLOOKUP(P10,tables!A:A,tables!C:C) -> LocalDateTable_53e9f058-843e-49fd-93b7-86c8e4083f27 | R10: 3961 | S10: =_xlfn.XLOOKUP(R10,columns!A:A,columns!C:C) -> 0 | T10: 1 | U10: =IF(T10=2,"Many","One") -> One | V10: =O10 &"-to-"&U10 -> Many-to-One | W10: 1 | X10: 5482 | Z10: 45967.778 | AA10: 45967.778 | AB10: 1
A11: 10361 | B11: 1 | C11: 877316de-440c-4f83-b485-f88083dbbe34 | D11: True | E11: 1 | F11: 1 | G11: =IF(F11=1,"Single", "Both") -> Single | H11: 2 | I11: False | J11: 10232 | K11: =_xlfn.XLOOKUP(J11,tables!A:A,tables!C:C) -> Calendario | L11: 10282 | M11: Fecha | N11: 2 | O11: =IF(N11=2,"Many","One") -> Many | P11: 10352 | Q11: =_xlfn.XLOOKUP(P11,tables!A:A,tables!C:C) -> LocalDateTable_bb815d3e-4cfd-4413-bfc9-f116f4ca9ef5 | R11: 10364 | S11: =_xlfn.XLOOKUP(R11,columns!A:A,columns!C:C) -> 0 | T11: 1 | U11: =IF(T11=2,"Many","One") -> One | V11: =O11 &"-to-"&U11 -> Many-to-One | W11: 1 | X11: 10593 | Z11: 45967.796 | AA11: 45967.796 | AB11: 1
A12: 10362 | B12: 1 | C12: 32ee34c9-b417-47c0-bdec-21f80903a39c | D12: True | E12: 1 | F12: 1 | G12: =IF(F12=1,"Single", "Both") -> Single | H12: 2 | I12: False | J12: 10232 | K12: =_xlfn.XLOOKUP(J12,tables!A:A,tables!C:C) -> Calendario | L12: 10296 | M12: PrimerDiaMes | N12: 2 | O12: =IF(N12=2,"Many","One") -> Many | P12: 10355 | Q12: =_xlfn.XLOOKUP(P12,tables!A:A,tables!C:C) -> LocalDateTable_89cc49f6-f68f-4820-9e32-b1175e645063 | R12: 10371 | S12: =_xlfn.XLOOKUP(R12,columns!A:A,columns!C:C) -> 0 | T12: 1 | U12: =IF(T12=2,"Many","One") -> One | V12: =O12 &"-to-"&U12 -> Many-to-One | W12: 1 | X12: 10595 | Z12: 45967.796 | AA12: 45967.796 | AB12: 1
A13: 10363 | B13: 1 | C13: ee256e21-7e96-4d26-ae3e-d4e2ed58ab1e | D13: True | E13: 1 | F13: 1 | G13: =IF(F13=1,"Single", "Both") -> Single | H13: 2 | I13: False | J13: 10232 | K13: =_xlfn.XLOOKUP(J13,tables!A:A,tables!C:C) -> Calendario | L13: 10298 | M13: FinMes | N13: 2 | O13: =IF(N13=2,"Many","One") -> Many | P13: 10358 | Q13: =_xlfn.XLOOKUP(P13,tables!A:A,tables!C:C) -> LocalDateTable_d78c9103-9f82-4378-9ee1-8323e716fec9 | R13: 10378 | S13: =_xlfn.XLOOKUP(R13,columns!A:A,columns!C:C) -> 0 | T13: 1 | U13: =IF(T13=2,"Many","One") -> One | V13: =O13 &"-to-"&U13 -> Many-to-One | W13: 1 | X13: 10597 | Z13: 45967.796 | AA13: 45967.796 | AB13: 1
A14: 11523 | B14: 1 | C14: 77f6ce2b-ee06-dad1-7cec-6a83dc995aaa | D14: True | E14: 1 | F14: 1 | G14: =IF(F14=1,"Single", "Both") -> Single | H14: 1 | I14: False | J14: 3734 | K14: =_xlfn.XLOOKUP(J14,tables!A:A,tables!C:C) -> fact_c_diaria | L14: 3830 | M14: =_xlfn.XLOOKUP(L14,columns!A:A,columns!C:C) -> fecha | N14: 2 | O14: =IF(N14=2,"Many","One") -> Many | P14: 10232 | Q14: =_xlfn.XLOOKUP(P14,tables!A:A,tables!C:C) -> Calendario | R14: 10282 | S14: =_xlfn.XLOOKUP(R14,columns!A:A,columns!C:C) -> Fecha | T14: 1 | U14: =IF(T14=2,"Many","One") -> One | V14: =O14 &"-to-"&U14 -> Many-to-One | W14: 1 | X14: 11524 | Z14: 45967.799 | AA14: 45967.799 | AB14: 1
A15: 11543 | B15: 1 | C15: dedbd68c-c2e2-d716-29de-6bce8909a206 | D15: True | E15: 1 | F15: 1 | G15: =IF(F15=1,"Single", "Both") -> Single | H15: 1 | I15: False | J15: 3740 | K15: =_xlfn.XLOOKUP(J15,tables!A:A,tables!C:C) -> fact_creditos | L15: 3857 | M15: =_xlfn.XLOOKUP(L15,columns!A:A,columns!C:C) -> fecha_corte | N15: 2 | O15: =IF(N15=2,"Many","One") -> Many | P15: 10232 | Q15: =_xlfn.XLOOKUP(P15,tables!A:A,tables!C:C) -> Calendario | R15: 10282 | S15: =_xlfn.XLOOKUP(R15,columns!A:A,columns!C:C) -> Fecha | T15: 1 | U15: =IF(T15=2,"Many","One") -> One | V15: =O15 &"-to-"&U15 -> Many-to-One | W15: 1 | X15: 11544 | Z15: 45967.799 | AA15: 45967.799 | AB15: 1
A16: 11560 | B16: 1 | C16: 04f29f96-70e6-f04a-0a4f-ea355fa44639 | D16: True | E16: 1 | F16: 1 | G16: =IF(F16=1,"Single", "Both") -> Single | H16: 1 | I16: False | J16: 3752 | K16: =_xlfn.XLOOKUP(J16,tables!A:A,tables!C:C) -> fact_inversiones | L16: 3881 | M16: =_xlfn.XLOOKUP(L16,columns!A:A,columns!C:C) -> fecha_monto | N16: 2 | O16: =IF(N16=2,"Many","One") -> Many | P16: 10232 | Q16: =_xlfn.XLOOKUP(P16,tables!A:A,tables!C:C) -> Calendario | R16: 10282 | S16: =_xlfn.XLOOKUP(R16,columns!A:A,columns!C:C) -> Fecha | T16: 1 | U16: =IF(T16=2,"Many","One") -> One | V16: =O16 &"-to-"&U16 -> Many-to-One | W16: 1 | X16: 11561 | Z16: 45967.799 | AA16: 45967.799 | AB16: 1
A17: 11580 | B17: 1 | C17: 907b7dff-9d55-8e0c-8907-58fd0edc5970 | D17: True | E17: 1 | F17: 1 | G17: =IF(F17=1,"Single", "Both") -> Single | H17: 1 | I17: False | J17: 3758 | K17: =_xlfn.XLOOKUP(J17,tables!A:A,tables!C:C) -> fact_parametros | L17: 3895 | M17: =_xlfn.XLOOKUP(L17,columns!A:A,columns!C:C) -> fecha_captura | N17: 2 | O17: =IF(N17=2,"Many","One") -> Many | P17: 10232 | Q17: =_xlfn.XLOOKUP(P17,tables!A:A,tables!C:C) -> Calendario | R17: 10282 | S17: =_xlfn.XLOOKUP(R17,columns!A:A,columns!C:C) -> Fecha | T17: 1 | U17: =IF(T17=2,"Many","One") -> One | V17: =O17 &"-to-"&U17 -> Many-to-One | W17: 1 | X17: 11581 | Z17: 45967.8 | AA17: 45967.8 | AB17: 1
A18: 12605 | B18: 1 | C18: 8f542c5d-e9b8-fcf5-5dd7-a4760c8b6118 | D18: True | E18: 1 | F18: 1 | G18: =IF(F18=1,"Single", "Both") -> Single | H18: 1 | I18: False | J18: 11641 | K18: =_xlfn.XLOOKUP(J18,tables!A:A,tables!C:C) -> ds_presupuesto_mensual_regular_dinero | L18: 11662 | M18: =_xlfn.XLOOKUP(L18,columns!A:A,columns!C:C) -> mes_regular_dinero | N18: 2 | O18: =IF(N18=2,"Many","One") -> Many | P18: 10232 | Q18: =_xlfn.XLOOKUP(P18,tables!A:A,tables!C:C) -> Calendario | R18: 10282 | S18: =_xlfn.XLOOKUP(R18,columns!A:A,columns!C:C) -> Fecha | T18: 1 | U18: =IF(T18=2,"Many","One") -> One | V18: =O18 &"-to-"&U18 -> Many-to-One | W18: 1 | X18: 12606 | Z18: 45967.872 | AA18: 45967.872 | AB18: 1
A19: 12622 | B19: 1 | C19: b8d02804-37a4-c364-487f-5a4625be7ce8 | D19: True | E19: 1 | F19: 1 | G19: =IF(F19=1,"Single", "Both") -> Single | H19: 1 | I19: False | J19: 11635 | K19: =_xlfn.XLOOKUP(J19,tables!A:A,tables!C:C) -> ds_presupuesto_mensual_especifico | L19: 11652 | M19: =_xlfn.XLOOKUP(L19,columns!A:A,columns!C:C) -> inicio_mes | N19: 2 | O19: =IF(N19=2,"Many","One") -> Many | P19: 10232 | Q19: =_xlfn.XLOOKUP(P19,tables!A:A,tables!C:C) -> Calendario | R19: 10282 | S19: =_xlfn.XLOOKUP(R19,columns!A:A,columns!C:C) -> Fecha | T19: 1 | U19: =IF(T19=2,"Many","One") -> One | V19: =O19 &"-to-"&U19 -> Many-to-One | W19: 1 | X19: 12623 | Z19: 45967.873 | AA19: 45967.873 | AB19: 1
A20: 12645 | B20: 1 | C20: bbf76540-689d-b1fa-ca76-6c5db5fb8669 | D20: True | E20: 1 | F20: 1 | G20: =IF(F20=1,"Single", "Both") -> Single | H20: 1 | I20: False | J20: 11635 | K20: =_xlfn.XLOOKUP(J20,tables!A:A,tables!C:C) -> ds_presupuesto_mensual_especifico | L20: 11649 | M20: =_xlfn.XLOOKUP(L20,columns!A:A,columns!C:C) -> id_presupuesto_mensual | N20: 2 | O20: =IF(N20=2,"Many","One") -> Many | P20: 3764 | Q20: =_xlfn.XLOOKUP(P20,tables!A:A,tables!C:C) -> fact_presupuesto | R20: 3905 | S20: =_xlfn.XLOOKUP(R20,columns!A:A,columns!C:C) -> id_presupuesto_mensual | T20: 1 | U20: =IF(T20=2,"Many","One") -> One | V20: =O20 &"-to-"&U20 -> Many-to-One | W20: 1 | X20: 12646 | Z20: 45967.874 | AA20: 45967.874 | AB20: 1
A21: 12662 | B21: 1 | C21: 082c703a-592a-43e0-b969-da699a3f9e83 | D21: True | E21: 1 | F21: 1 | G21: =IF(F21=1,"Single", "Both") -> Single | H21: 1 | I21: False | J21: 11641 | K21: =_xlfn.XLOOKUP(J21,tables!A:A,tables!C:C) -> ds_presupuesto_mensual_regular_dinero | L21: 11661 | M21: =_xlfn.XLOOKUP(L21,columns!A:A,columns!C:C) -> id_presupuesto_mensual | N21: 2 | O21: =IF(N21=2,"Many","One") -> Many | P21: 3764 | Q21: =_xlfn.XLOOKUP(P21,tables!A:A,tables!C:C) -> fact_presupuesto | R21: 3905 | S21: =_xlfn.XLOOKUP(R21,columns!A:A,columns!C:C) -> id_presupuesto_mensual | T21: 1 | U21: =IF(T21=2,"Many","One") -> One | V21: =O21 &"-to-"&U21 -> Many-to-One | W21: 1 | X21: 12663 | Z21: 45967.874 | AA21: 45967.874 | AB21: 1
A22: 12682 | B22: 1 | C22: 56c96849-8cb6-a55f-bf3f-bdd5c658fa9f | D22: True | E22: 1 | F22: 1 | G22: =IF(F22=1,"Single", "Both") -> Single | H22: 1 | I22: False | J22: 3803 | K22: =_xlfn.XLOOKUP(J22,tables!A:A,tables!C:C) -> ds_viaje_tipo_cambio | L22: 3981 | M22: =_xlfn.XLOOKUP(L22,columns!A:A,columns!C:C) -> id | N22: 2 | O22: =IF(N22=2,"Many","One") -> Many | P22: 3734 | Q22: =_xlfn.XLOOKUP(P22,tables!A:A,tables!C:C) -> fact_c_diaria | R22: 3829 | S22: =_xlfn.XLOOKUP(R22,columns!A:A,columns!C:C) -> id | T22: 1 | U22: =IF(T22=2,"Many","One") -> One | V22: =O22 &"-to-"&U22 -> Many-to-One | W22: 1 | X22: 12683 | Z22: 45968.724 | AA22: 45968.724 | AB22: 1
A23: 12702 | B23: 1 | C23: 43194a4b-c9cb-6d8a-1e24-69ca7a63394b | D23: True | E23: 1 | F23: 1 | G23: =IF(F23=1,"Single", "Both") -> Single | H23: 1 | I23: False | J23: 19 | K23: =_xlfn.XLOOKUP(J23,tables!A:A,tables!C:C) -> ds_creditos_periodo | L23: 28 | M23: =_xlfn.XLOOKUP(L23,columns!A:A,columns!C:C) -> id | N23: 2 | O23: =IF(N23=2,"Many","One") -> Many | P23: 3734 | Q23: =_xlfn.XLOOKUP(P23,tables!A:A,tables!C:C) -> fact_c_diaria | R23: 3829 | S23: =_xlfn.XLOOKUP(R23,columns!A:A,columns!C:C) -> id | T23: 1 | U23: =IF(T23=2,"Many","One") -> One | V23: =O23 &"-to-"&U23 -> Many-to-One | W23: 1 | X23: 12703 | Z23: 45968.725 | AA23: 45968.725 | AB23: 1
A24: 12722 | B24: 1 | C24: 680b9a9e-e3a6-3b7d-cbd0-bec1d1313f6f | D24: True | E24: 1 | F24: 1 | G24: =IF(F24=1,"Single", "Both") -> Single | H24: 1 | I24: False | J24: 415 | K24: =_xlfn.XLOOKUP(J24,tables!A:A,tables!C:C) -> ds_inversiones_movimientos | L24: 469 | M24: =_xlfn.XLOOKUP(L24,columns!A:A,columns!C:C) -> id | N24: 2 | O24: =IF(N24=2,"Many","One") -> Many | P24: 3734 | Q24: =_xlfn.XLOOKUP(P24,tables!A:A,tables!C:C) -> fact_c_diaria | R24: 3829 | S24: =_xlfn.XLOOKUP(R24,columns!A:A,columns!C:C) -> id | T24: 1 | U24: =IF(T24=2,"Many","One") -> One | V24: =O24 &"-to-"&U24 -> Many-to-One | W24: 1 | X24: 12723 | Z24: 45968.725 | AA24: 45968.725 | AB24: 1
A25: 12742 | B25: 1 | C25: ae65b710-58bc-ad3d-9e55-189705ea8973 | D25: True | E25: 1 | F25: 1 | G25: =IF(F25=1,"Single", "Both") -> Single | H25: 1 | I25: False | J25: 400 | K25: =_xlfn.XLOOKUP(J25,tables!A:A,tables!C:C) -> ds_deuda_id | L25: 444 | M25: =_xlfn.XLOOKUP(L25,columns!A:A,columns!C:C) -> id | N25: 2 | O25: =IF(N25=2,"Many","One") -> Many | P25: 3734 | Q25: =_xlfn.XLOOKUP(P25,tables!A:A,tables!C:C) -> fact_c_diaria | R25: 3829 | S25: =_xlfn.XLOOKUP(R25,columns!A:A,columns!C:C) -> id | T25: 1 | U25: =IF(T25=2,"Many","One") -> One | V25: =O25 &"-to-"&U25 -> Many-to-One | W25: 1 | X25: 12743 | Z25: 45968.725 | AA25: 45968.725 | AB25: 1
... A43: 13425 | B43: 1 | C43: ea0854ee-649b-e9c0-ecae-376a1308798e | D43: True | E43: 1 | F43: 1 | G43: =IF(F43=1,"Single", "Both") -> Single | H43: 1 | I43: False | J43: 3785 | K43: =_xlfn.XLOOKUP(J43,tables!A:A,tables!C:C) -> dim_id_viajes | L43: 3949 | M43: =_xlfn.XLOOKUP(L43,columns!A:A,columns!C:C) -> ubicacion_viajes | N43: 2 | O43: =IF(N43=2,"Many","One") -> Many | P43: 3779 | Q43: =_xlfn.XLOOKUP(P43,tables!A:A,tables!C:C) -> dim_geografia | R43: 3933 | S43: =_xlfn.XLOOKUP(R43,columns!A:A,columns!C:C) -> ubicacion_viajes | T43: 1 | U43: =IF(T43=2,"Many","One") -> One | V43: =O43 &"-to-"&U43 -> Many-to-One | W43: 1 | X43: 13426 | Z43: 45968.767 | AA43: 45968.767 | AB43: 1

Sheet final_formulado
A1: =relationships!J1 -> FromTableID | B1: =relationships!L1 -> FromColumnID | C1: =relationships!V1 -> Cardinality | D1: =relationships!P1 -> ToTableID | E1: =relationships!R1 -> ToColumnID | F1: =relationships!F1 -> CrossFilteringBehavior | G1: =relationships!D1 -> IsActive
A2: =relationships!K14 -> fact_c_diaria | B2: =relationships!M14 -> fecha | C2: =relationships!V2 -> Many-to-One | D2: =relationships!Q14 -> Calendario | E2: =relationships!S14 -> Fecha | F2: =relationships!G2 -> Single | G2: =relationships!D14 -> True
A3: =relationships!K15 -> fact_creditos | B3: =relationships!M15 -> fecha_corte | C3: =relationships!V3 -> Many-to-One | D3: =relationships!Q15 -> Calendario | E3: =relationships!S15 -> Fecha | F3: =relationships!G3 -> Single | G3: =relationships!D15 -> True
A4: =relationships!K16 -> fact_inversiones | B4: =relationships!M16 -> fecha_monto | C4: =relationships!V4 -> Many-to-One | D4: =relationships!Q16 -> Calendario | E4: =relationships!S16 -> Fecha | F4: =relationships!G4 -> Single | G4: =relationships!D16 -> True
A5: =relationships!K17 -> fact_parametros | B5: =relationships!M17 -> fecha_captura | C5: =relationships!V5 -> Many-to-One | D5: =relationships!Q17 -> Calendario | E5: =relationships!S17 -> Fecha | F5: =relationships!G5 -> Single | G5: =relationships!D17 -> True
A6: =relationships!K18 -> ds_presupuesto_mensual_regular_dinero | B6: =relationships!M18 -> mes_regular_dinero | C6: =relationships!V6 -> Many-to-One | D6: =relationships!Q18 -> Calendario | E6: =relationships!S18 -> Fecha | F6: =relationships!G6 -> Single | G6: =relationships!D18 -> True
A7: =relationships!K19 -> ds_presupuesto_mensual_especifico | B7: =relationships!M19 -> inicio_mes | C7: =relationships!V7 -> Many-to-One | D7: =relationships!Q19 -> Calendario | E7: =relationships!S19 -> Fecha | F7: =relationships!G7 -> Single | G7: =relationships!D19 -> True
A8: =relationships!K20 -> ds_presupuesto_mensual_especifico | B8: =relationships!M20 -> id_presupuesto_mensual | C8: =relationships!V8 -> Many-to-One | D8: =relationships!Q20 -> fact_presupuesto | E8: =relationships!S20 -> id_presupuesto_mensual | F8: =relationships!G8 -> Single | G8: =relationships!D20 -> True
A9: =relationships!K21 -> ds_presupuesto_mensual_regular_dinero | B9: =relationships!M21 -> id_presupuesto_mensual | C9: =relationships!V9 -> Many-to-One | D9: =relationships!Q21 -> fact_presupuesto | E9: =relationships!S21 -> id_presupuesto_mensual | F9: =relationships!G9 -> Single | G9: =relationships!D21 -> True
A10: =relationships!K22 -> ds_viaje_tipo_cambio | B10: =relationships!M22 -> id | C10: =relationships!V10 -> Many-to-One | D10: =relationships!Q22 -> fact_c_diaria | E10: =relationships!S22 -> id | F10: =relationships!G10 -> Single | G10: =relationships!D22 -> True
A11: =relationships!K23 -> ds_creditos_periodo | B11: =relationships!M23 -> id | C11: =relationships!V11 -> Many-to-One | D11: =relationships!Q23 -> fact_c_diaria | E11: =relationships!S23 -> id | F11: =relationships!G11 -> Single | G11: =relationships!D23 -> True
A12: =relationships!K24 -> ds_inversiones_movimientos | B12: =relationships!M24 -> id | C12: =relationships!V12 -> Many-to-One | D12: =relationships!Q24 -> fact_c_diaria | E12: =relationships!S24 -> id | F12: =relationships!G12 -> Single | G12: =relationships!D24 -> True
A13: =relationships!K25 -> ds_deuda_id | B13: =relationships!M25 -> id | C13: =relationships!V13 -> Many-to-One | D13: =relationships!Q25 -> fact_c_diaria | E13: =relationships!S25 -> id | F13: =relationships!G13 -> Single | G13: =relationships!D25 -> True
A14: =relationships!K27 -> ds_presupuesto_especifico | B14: =relationships!M27 -> id | C14: =relationships!V15 -> Many-to-One | D14: =relationships!Q27 -> fact_c_diaria | E14: =relationships!S27 -> id | F14: =relationships!G15 -> Single | G14: =relationships!D27 -> True
A15: =relationships!K28 -> ds_viaje_id | B15: =relationships!M28 -> id | C15: =relationships!V16 -> Many-to-One | D15: =relationships!Q28 -> fact_c_diaria | E15: =relationships!S28 -> id | F15: =relationships!G16 -> Single | G15: =relationships!D28 -> True
A16: =relationships!K29 -> ds_deuda_id | B16: =relationships!M29 -> id_deuda | C16: =relationships!V17 -> Many-to-One | D16: =relationships!Q29 -> dim_id_deuda | E16: =relationships!S29 -> id_deuda | F16: =relationships!G17 -> Single | G16: =relationships!D29 -> True
A17: =relationships!K30 -> ds_deuda_id | B17: =relationships!M30 -> nombre_deudor | C17: =relationships!V18 -> Many-to-One | D17: =relationships!Q30 -> dim_deuda_nombre | E17: =relationships!S30 -> nombre_deudor | F17: =relationships!G18 -> Single | G17: =relationships!D30 -> True
A18: =relationships!K31 -> ds_creditos_periodo | B18: =relationships!M31 -> tipo_credito | C18: =relationships!V19 -> Many-to-One | D18: =relationships!Q31 -> dim_tipo_credito | E18: =relationships!S31 -> tipo_credito | F18: =relationships!G19 -> Single | G18: =relationships!D31 -> True
A19: =relationships!K32 -> ds_inversiones_movimientos | B19: =relationships!M32 -> categoria_movimiento | C19: =relationships!V20 -> Many-to-One | D19: =relationships!Q32 -> dim_categoria_movimiento | E19: =relationships!S32 -> categoria_movimiento | F19: =relationships!G20 -> Single | G19: =relationships!D32 -> True
A20: =relationships!K33 -> ds_inversiones_movimientos | B20: =relationships!M33 -> tipo_inversion_detectado | C20: =relationships!V21 -> Many-to-One | D20: =relationships!Q33 -> dim_tipo_inversion | E20: =relationships!S33 -> tipo_inversion | F20: =relationships!G21 -> Single | G20: =relationships!D33 -> True
A21: =relationships!K34 -> ds_viaje_id | B21: =relationships!M34 -> id_viaje | C21: =relationships!V22 -> Many-to-One | D21: =relationships!Q34 -> dim_id_viajes | E21: =relationships!S34 -> id_viaje | F21: =relationships!G22 -> Single | G21: =relationships!D34 -> True
A22: =relationships!K35 -> ds_viaje_id | B22: =relationships!M35 -> grupo_viaje | C22: =relationships!V23 -> Many-to-One | D22: =relationships!Q35 -> dim_viajes_grupo | E22: =relationships!S35 -> grupo_viaje | F22: =relationships!G23 -> Single | G22: =relationships!D35 -> True
A23: =relationships!K36 -> ds_viajes_url | B23: =relationships!M36 -> id_viaje | C23: =relationships!V24 -> Many-to-One | D23: =relationships!Q36 -> dim_id_viajes | E23: =relationships!S36 -> id_viaje | F23: =relationships!G24 -> Single | G23: =relationships!D36 -> True
A24: =relationships!K37 -> ds_presupuesto_especifico | B24: =relationships!M37 -> id_presupuesto | C24: =relationships!V25 -> Many-to-One | D24: =relationships!Q37 -> dim_id_presupuesto | E24: =relationships!S37 -> id_presupuesto | F24: =relationships!G25 -> Single | G24: =relationships!D37 -> True
A25: =relationships!K38 -> fact_presupuesto | B25: =relationships!M38 -> razon_uso | C25: =relationships!V26 -> Many-to-One | D25: =relationships!Q38 -> dim_razon_uso | E25: =relationships!S38 -> razon_uso | F25: =relationships!G26 -> Single | G25: =relationships!D38 -> True
... A30: =relationships!K43 -> dim_id_viajes | B30: =relationships!M43 -> ubicacion_viajes | C30: =relationships!V31 -> Many-to-One | D30: =relationships!Q43 -> dim_geografia | E30: =relationships!S43 -> ubicacion_viajes | F30: =relationships!G31 -> Single | G30: =relationships!D43 -> True

Sheet Hoja7
A1: FromTableID | B1: FromColumnID | C1: Cardinality | D1: ToTableID | E1: ToColumnID | F1: CrossFilteringBehavior | G1: IsActive | H1: razon_uso
A2: fact_c_diaria | B2: fecha | C2: Many-to-One | D2: Calendario | E2: Fecha | F2: Single | G2: True | H2: =IF(OR(ISNUMBER(SEARCH($H$1,A2)),ISNUMBER(SEARCH($H$1,D2))),"Si","No") -> No
A3: fact_creditos | B3: primer_dia_mes_corte | C3: Many-to-One | D3: Calendario | E3: Fecha | F3: Single | G3: True | H3: =IF(OR(ISNUMBER(SEARCH($H$1,A3)),ISNUMBER(SEARCH($H$1,D3))),"Si","No") -> No
A4: fact_inversiones | B4: fecha_monto | C4: Many-to-One | D4: Calendario | E4: Fecha | F4: Single | G4: True | H4: =IF(OR(ISNUMBER(SEARCH($H$1,A4)),ISNUMBER(SEARCH($H$1,D4))),"Si","No") -> No
A5: fact_parametros | B5: fecha_captura | C5: Many-to-One | D5: Calendario | E5: Fecha | F5: Single | G5: True | H5: =IF(OR(ISNUMBER(SEARCH($H$1,A5)),ISNUMBER(SEARCH($H$1,D5))),"Si","No") -> No
A6: ds_presupuesto_mensual_regular_dinero | B6: mes_regular_dinero | C6: Many-to-One | D6: Calendario | E6: Fecha | F6: Single | G6: True | H6: =IF(OR(ISNUMBER(SEARCH($H$1,A6)),ISNUMBER(SEARCH($H$1,D6))),"Si","No") -> No
A7: ds_presupuesto_mensual_especifico | B7: inicio_mes | C7: Many-to-One | D7: Calendario | E7: Fecha | F7: Single | G7: True | H7: =IF(OR(ISNUMBER(SEARCH($H$1,A7)),ISNUMBER(SEARCH($H$1,D7))),"Si","No") -> No
A8: ds_presupuesto_mensual_especifico | B8: id_presupuesto_mensual | C8: Many-to-One | D8: fact_presupuesto | E8: id_presupuesto_mensual | F8: Single | G8: True | H8: =IF(OR(ISNUMBER(SEARCH($H$1,A8)),ISNUMBER(SEARCH($H$1,D8))),"Si","No") -> No
A9: ds_presupuesto_mensual_regular_dinero | B9: id_presupuesto_mensual | C9: Many-to-One | D9: fact_presupuesto | E9: id_presupuesto_mensual | F9: Single | G9: True | H9: =IF(OR(ISNUMBER(SEARCH($H$1,A9)),ISNUMBER(SEARCH($H$1,D9))),"Si","No") -> No
A10: ds_viaje_tipo_cambio | B10: id | C10: Many-to-One | D10: fact_c_diaria | E10: id | F10: Single | G10: True | H10: =IF(OR(ISNUMBER(SEARCH($H$1,A10)),ISNUMBER(SEARCH($H$1,D10))),"Si","No") -> No
A11: fact_c_diaria | B11: id | C11: Many-to-One | D11: ds_creditos_periodo | E11: id | F11: Single | G11: True | H11: =IF(OR(ISNUMBER(SEARCH($H$1,D11)),ISNUMBER(SEARCH($H$1,#REF!))),"Si","No") -> No
A12: fact_c_diaria | B12: id | C12: Many-to-One | D12: ds_inversiones_movimientos | E12: id | F12: Single | G12: True | H12: =IF(OR(ISNUMBER(SEARCH($H$1,A12)),ISNUMBER(SEARCH($H$1,D12))),"Si","No") -> No
A13: fact_c_diaria | B13: id | C13: Many-to-One | D13: ds_deuda_id | E13: id | F13: Single | G13: True | H13: =IF(OR(ISNUMBER(SEARCH($H$1,A13)),ISNUMBER(SEARCH($H$1,D13))),"Si","No") -> No
A14: fact_c_diaria | B14: id | C14: Many-to-One | D14: ds_presupuesto_aplicado | E14: id | F14: Both | G14: True | H14: =IF(OR(ISNUMBER(SEARCH($H$1,D14)),ISNUMBER(SEARCH($H$1,#REF!))),"Si","No") -> No
A15: ds_viaje_id | B15: id | C15: Many-to-One | D15: fact_c_diaria | E15: id | F15: Single | G15: True | H15: =IF(OR(ISNUMBER(SEARCH($H$1,A15)),ISNUMBER(SEARCH($H$1,D15))),"Si","No") -> No
A16: ds_deuda_id | B16: id_deuda | C16: Many-to-One | D16: dim_id_deuda | E16: id_deuda | F16: Single | G16: True | H16: =IF(OR(ISNUMBER(SEARCH($H$1,A16)),ISNUMBER(SEARCH($H$1,D16))),"Si","No") -> No
A17: ds_deuda_id | B17: nombre_deudor | C17: Many-to-One | D17: dim_deuda_nombre | E17: nombre_deudor | F17: Both | G17: True | H17: =IF(OR(ISNUMBER(SEARCH($H$1,A17)),ISNUMBER(SEARCH($H$1,D17))),"Si","No") -> No
A18: ds_creditos_periodo | B18: tipo_credito | C18: Many-to-One | D18: dim_tipo_credito | E18: tipo_credito | F18: Single | G18: True | H18: =IF(OR(ISNUMBER(SEARCH($H$1,A18)),ISNUMBER(SEARCH($H$1,D18))),"Si","No") -> No
A19: ds_inversiones_movimientos | B19: tipo_inversion_detectado | C19: Many-to-One | D19: tipo_inversion_detectado | E19: categoria_movimiento | F19: Both | G19: True | H19: =IF(OR(ISNUMBER(SEARCH($H$1,A19)),ISNUMBER(SEARCH($H$1,D19))),"Si","No") -> No
A20: fact_inversiones | B20: tipo_inversion | C20: Many-to-One | D20: dim_tipo_inversion | E20: tipo_inversion | F20: Single | G20: True | H20: =IF(OR(ISNUMBER(SEARCH($H$1,A20)),ISNUMBER(SEARCH($H$1,D20))),"Si","No") -> No
A21: ds_viaje_id | B21: id_viaje | C21: Many-to-One | D21: dim_id_viajes | E21: id_viaje | F21: Single | G21: True | H21: =IF(OR(ISNUMBER(SEARCH($H$1,A21)),ISNUMBER(SEARCH($H$1,D21))),"Si","No") -> No
A22: dim_id_viajes | B22: grupo_viaje | C22: Many-to-One | D22: dim_viajes_grupo | E22: grupo_viaje | F22: Single | G22: True | H22: =IF(OR(ISNUMBER(SEARCH($H$1,A22)),ISNUMBER(SEARCH($H$1,D22))),"Si","No") -> No
A23: ds_viajes_url | B23: id_viaje | C23: Many-to-One | D23: dim_id_viajes | E23: id_viaje | F23: Single | G23: True | H23: =IF(OR(ISNUMBER(SEARCH($H$1,A23)),ISNUMBER(SEARCH($H$1,D23))),"Si","No") -> No
A24: ds_presupuesto_aplicado | B24: id_presupuesto | C24: Many-to-One | D24: dim_id_presupuesto | E24: id_presupuesto | F24: Single | G24: True | H24: =IF(OR(ISNUMBER(SEARCH($H$1,A24)),ISNUMBER(SEARCH($H$1,D24))),"Si","No") -> No
A25: fact_presupuesto | B25: razon_uso | C25: Many-to-One | D25: dim_razon_uso | E25: razon_uso | F25: Single | G25: True | H25: =IF(OR(ISNUMBER(SEARCH($H$1,A25)),ISNUMBER(SEARCH($H$1,D25))),"Si","No") -> Si
A26: fact_c_diaria | B26: razon_uso | C26: Many-to-One | D26: dim_razon_uso | E26: razon_uso | F26: Single | G26: True | H26: =IF(OR(ISNUMBER(SEARCH($H$1,A26)),ISNUMBER(SEARCH($H$1,D26))),"Si","No") -> Si
... A41: ds_ingresos | B41: canal_ingreso | C41: Many-to-One | D41: dim_canal_ingreso | E41: canal_ingreso | F41: Both | G41: True | H41: =IF(OR(ISNUMBER(SEARCH($H$1,A41)),ISNUMBER(SEARCH($H$1,D41))),"Si","No") -> No
